<?xml version="1.0" encoding="utf-8"?>
<!-- This URDF was automatically created by SolidWorks to URDF Exporter! Originally created by Stephen Brawner (brawner@gmail.com) 
     Commit Version: 1.5.0-0-g9aa0fdb  Build Version: 1.5.7004.21443
     For more information, please see http://wiki.ros.org/sw_urdf_exporter -->
<robot
  name="sunny_gazebo">
  <link
    name="base_link">
    <inertial>
      <origin
        xyz="0.17501 0.00094708 0.53203"
        rpy="0 0 0" />
      <mass
        value="18.546" />
      <inertia
        ixx="0.99947"
        ixy="-0.0015622"
        ixz="0.074343"
        iyy="0.53931"
        iyz="0.00096877"
        izz="1.0754" />
    </inertial>
    <visual>
      <origin
        xyz="0 0 0"
        rpy="0 0 0" />
      <geometry>
        <mesh
          filename="package://sunny_gazebo/meshes/base_link.STL" />
      </geometry>
      <material
        name="">
        <color
          rgba="0.75294 0.75294 0.75294 1" />
      </material>
    </visual>
    <collision>
      <origin
        xyz="0 0 0"
        rpy="0 0 0" />
      <geometry>
        <mesh
          filename="package://sunny_gazebo/meshes/base_link.STL" />
      </geometry>
    </collision>
  </link>
  <link
    name="universal_wheel_link">
    <inertial>
      <origin
        xyz="-0.0015321 -3.3133E-08 -0.0047949"
        rpy="0 0 0" />
      <mass
        value="0.10446" />
      <inertia
        ixx="0.00013522"
        ixy="-3.8014E-11"
        ixz="-1.2947E-05"
        iyy="0.00015124"
        iyz="-2.1959E-10"
        izz="0.00018481" />
    </inertial>
    <visual>
      <origin
        xyz="0 0 0"
        rpy="0 0 0" />
      <geometry>
        <mesh
          filename="package://sunny_gazebo/meshes/universal_wheel_link.STL" />
      </geometry>
      <material
        name="">
        <color
          rgba="1 1 1 1" />
      </material>
    </visual>
    <collision>
      <origin
        xyz="0 0 0"
        rpy="0 0 0" />
      <geometry>
        <mesh
          filename="package://sunny_gazebo/meshes/universal_wheel_link.STL" />
      </geometry>
    </collision>
  </link>
  <joint
    name="joint_uw"
    type="continuous">
    <origin
      xyz="0.48 0 0.069"
      rpy="0 0 0" />
    <parent
      link="base_link" />
    <child
      link="universal_wheel_link" />
    <axis
      xyz="0 0 -1" />
    <safety_controller
      k_velocity="0" />
  </joint>
  <link
    name="front_wheel_link">
    <inertial>
      <origin
        xyz="0 0 -6.9389E-18"
        rpy="0 0 0" />
      <mass
        value="0.3927" />
      <inertia
        ixx="0.00032725"
        ixy="-2.2442E-20"
        ixz="-4.2592E-37"
        iyy="0.00049087"
        iyz="8.35E-21"
        izz="0.00032725" />
    </inertial>
    <visual>
      <origin
        xyz="0 0 0"
        rpy="0 0 0" />
      <geometry>
        <mesh
          filename="package://sunny_gazebo/meshes/front_wheel_link.STL" />
      </geometry>
      <material
        name="">
        <color
          rgba="1 1 1 1" />
      </material>
    </visual>
    <collision>
      <origin
        xyz="0 0 0"
        rpy="0 0 0" />
      <geometry>
        <mesh
          filename="package://sunny_gazebo/meshes/front_wheel_link.STL" />
      </geometry>
    </collision>
  </link>
  <joint
    name="joint_fw"
    type="continuous">
    <origin
      xyz="-0.020405 -0.00041802 -0.097845"
      rpy="0 0 0" />
    <parent
      link="universal_wheel_link" />
    <child
      link="front_wheel_link" />
    <axis
      xyz="0 1 0" />
    <safety_controller
      k_velocity="0" />
  </joint>
  <link
    name="left_wheel_link">
    <inertial>
      <origin
        xyz="1.431E-06 -0.0012631 -1.4578E-05"
        rpy="0 0 0" />
      <mass
        value="0.73904" />
      <inertia
        ixx="0.0011472"
        ixy="-8.5864E-08"
        ixz="-2.5883E-08"
        iyy="0.0019347"
        iyz="3.1564E-08"
        izz="0.0011471" />
    </inertial>
    <visual>
      <origin
        xyz="0 0 0"
        rpy="0 0 0" />
      <geometry>
        <mesh
          filename="package://sunny_gazebo/meshes/left_wheel_link.STL" />
      </geometry>
      <material
        name="">
        <color
          rgba="1 1 1 1" />
      </material>
    </visual>
    <collision>
      <origin
        xyz="0 0 0"
        rpy="0 0 0" />
      <geometry>
        <mesh
          filename="package://sunny_gazebo/meshes/left_wheel_link.STL" />
      </geometry>
    </collision>
  </link>
  <joint
    name="joint_lw"
    type="continuous">
    <origin
      xyz="0 0.289 0"
      rpy="0 0 0" />
    <parent
      link="base_link" />
    <child
      link="left_wheel_link" />
    <axis
      xyz="0 1 0" />
    <safety_controller
      k_velocity="0" />
  </joint>
  <link
    name="right_wheel_link">
    <inertial>
      <origin
        xyz="-1.431E-06 0.0012631 -1.4578E-05"
        rpy="0 0 0" />
      <mass
        value="0.73904" />
      <inertia
        ixx="0.0011472"
        ixy="-8.5864E-08"
        ixz="2.5883E-08"
        iyy="0.0019347"
        iyz="-3.1564E-08"
        izz="0.0011471" />
    </inertial>
    <visual>
      <origin
        xyz="0 0 0"
        rpy="0 0 0" />
      <geometry>
        <mesh
          filename="package://sunny_gazebo/meshes/right_wheel_link.STL" />
      </geometry>
      <material
        name="">
        <color
          rgba="1 1 1 1" />
      </material>
    </visual>
    <collision>
      <origin
        xyz="0 0 0"
        rpy="0 0 0" />
      <geometry>
        <mesh
          filename="package://sunny_gazebo/meshes/right_wheel_link.STL" />
      </geometry>
    </collision>
  </link>
  <joint
    name="joint_rw"
    type="continuous">
    <origin
      xyz="0 -0.289 0"
      rpy="0 0 0" />
    <parent
      link="base_link" />
    <child
      link="right_wheel_link" />
    <axis
      xyz="0 1 0" />
    <safety_controller
      k_velocity="0" />
  </joint>
</robot>