<?xml version="1.0"?>
<!-- This URDF was automatically created by SolidWorks to URDF Exporter! Originally created by Stephen Brawner (brawner@gmail.com) 
     Commit Version: 1.5.0-0-g9aa0fdb  Build Version: 1.5.7004.21443
     For more information, please see http://wiki.ros.org/sw_urdf_exporter -->
<robot
  name="sunny" xmlns:xacro="http://ros.org/wiki/xacro">
  <xacro:include filename="$(find sunny_gazebo)/urdf/sunny_model.gazebo.xacro"/>
  <xacro:include filename="$(find sunny_gazebo)/urdf/common_properties.xacro"/>
  <xacro:property name="M_PI" value="3.14159265358979323846"/> 
  <!-- Body -->
  <link
    name="base_link">
    <inertial>
      <origin
        xyz="0.20582 0.0014686 0.56216"
        rpy="0 0 0" />
      <mass
        value="1.5712" />
      <inertia
        ixx="0.093576"
        ixy="-0.00015797"
        ixz="0.0071338"
        iyy="0.052524"
        iyz="0.000094839"
        izz="0.10195" />
    </inertial>
    <visual>
      <origin
        xyz="0 0 0"
        rpy="0 0 0" />
      <geometry>
        <mesh
          filename="package://sunny_gazebo/meshes/base_link.dae" />
      </geometry>
      <material
        name="">
        <color
          rgba="0.75294 0.75294 0.75294 1" />
      </material>
    </visual>
    <collision>
      <origin
        xyz="0 0 0"
        rpy="0 0 0" />
      <geometry>
        <mesh
          filename="package://sunny_gazebo/meshes/base_link.dae" />
      </geometry>
      <surface>
        <friction>
          <ode>
            <mu>1.0</mu>
            <mu2>1.0</mu2>
          </ode>
        </friction>
      </surface>
    </collision>
  </link>

  <!-- Wheel -->
  <link
    name="universal_wheel_link">
    <inertial>
      <origin
        xyz="-0.0015321 -3.3133E-08 -0.012795"
        rpy="0 0 0" />
      <mass
        value="0.10446" />
      <inertia
        ixx="0.00013522"
        ixy="-3.8014E-11"
        ixz="-1.2947E-05"
        iyy="0.00015124"
        iyz="-2.1959E-10"
        izz="0.00018481" />
    </inertial>
    <visual>
      <origin
        xyz="0 0 0"
        rpy="0 0 0" />
      <geometry>
        <mesh
          filename="package://sunny_gazebo/meshes/universal_wheel_link.STL" />
      </geometry>
      <material
        name="">
        <color
          rgba="1 1 1 1" />
      </material>
    </visual>
    <collision>
      <origin
        xyz="0 0 0"
        rpy="0 0 0" />
      <geometry>
        <mesh
          filename="package://sunny_gazebo/meshes/universal_wheel_link.STL" />
      </geometry>
    </collision>
  </link>
  <joint
    name="joint_uw"
    type="continuous">
    <origin
      xyz="0.48 0 0.077"
      rpy="0 0 0" />
    <parent
      link="base_link" />
    <child
      link="universal_wheel_link" />
    <axis
      xyz="0 0 1" />
    <safety_controller
      k_velocity="0" />
  </joint>

  <link
    name="front_wheel_link">
    <inertial>
      <origin
        xyz="5.5511E-17 5.7406E-20 -3.4694E-18"
        rpy="0 0 0" />
      <mass
        value="3.927" />
      <inertia
        ixx="0.0032725"
        ixy="-2.2442E-19"
        ixz="2.0493E-36"
        iyy="0.0049087"
        iyz="8.35E-20"
        izz="0.0032725" />
    </inertial>
    <visual>
      <origin
        xyz="0 0 0"
        rpy="0 0 0" />
      <geometry>
        <mesh
          filename="package://sunny_gazebo/meshes/front_wheel_link.STL" />
      </geometry>
      <material
        name="">
        <color
          rgba="1 1 1 1" />
      </material>
    </visual>
    <collision>
      <origin
        xyz="0 0 0"
        rpy="0 0 0" />
      <geometry>
        <mesh
          filename="package://sunny_gazebo/meshes/front_wheel_link.STL" />
      </geometry>
      <surface>
        <friction>
          <ode>
            <mu>1.0</mu>
            <mu2>1.0</mu2>
          </ode>
        </friction>
      </surface>
    </collision>
  </link>
  <joint
    name="joint_fw"
    type="continuous">
    <origin
      xyz="-0.0405 0 -0.097"
      rpy="0 0 0" />
    <parent
      link="universal_wheel_link" />
    <child
      link="front_wheel_link" />
    <axis
      xyz="0 1 0" />
    <safety_controller
      k_velocity="0" />
  </joint>

  <link
    name="left_wheel_link">
    <inertial>
      <origin
        xyz="-1.0479E-14 0.0084162 -7.8679E-16"
        rpy="0 0 0" />
      <mass
        value="3.1181" />
      <inertia
        ixx="0.0063103"
        ixy="9.1891E-17"
        ixz="-8.4716E-18"
        iyy="0.011244"
        iyz="6.318E-17"
        izz="0.0063103" />
    </inertial>
    <visual>
      <origin
        xyz="0 0 0"
        rpy="0 0 0" />
      <geometry>
        <mesh
          filename="package://sunny_gazebo/meshes/left_wheel_link.STL" />
      </geometry>
      <material
        name="">
        <color
          rgba="1 1 1 1" />
      </material>
    </visual>
    <collision>
      <origin
        xyz="0 0 0"
        rpy="0 0 0" />
      <geometry>
        <mesh
          filename="package://sunny_gazebo/meshes/left_wheel_link.STL" />
      </geometry>
      <surface>
        <friction>
          <ode>
            <mu>1.0</mu>
            <mu2>1.0</mu2>
          </ode>
        </friction>
      </surface>
    </collision>
  </link>
  <joint
    name="joint_lw"
    type="continuous">
    <origin
      xyz="0 0.289 0"
      rpy="0 0 0" />
    <parent
      link="base_link" />
    <child
      link="left_wheel_link" />
    <axis
      xyz="0 1 0" />
    <dynamics
      friction = "1.0" />
    <safety_controller
      k_velocity="0" />
  </joint>

  <link
    name="right_wheel_link">
    <inertial>
      <origin
        xyz="-1.0479E-14 -0.0084162 -7.8679E-16"
        rpy="0 0 0" />
      <mass
        value="3.1181" />
      <inertia
        ixx="0.0063103"
        ixy="-9.1891E-17"
        ixz="-8.4716E-18"
        iyy="0.011244"
        iyz="-6.318E-17"
        izz="0.0063103" />
    </inertial>
    <visual>
      <origin
        xyz="0 0 0"
        rpy="0 0 0" />
      <geometry>
        <mesh
          filename="package://sunny_gazebo/meshes/right_wheel_link.STL" />
      </geometry>
      <material
        name="">
        <color
          rgba="1 1 1 1" />
      </material>
    </visual>
    <collision>
      <origin
        xyz="0 0 0"
        rpy="0 0 0" />
      <geometry>
        <mesh
          filename="package://sunny_gazebo/meshes/right_wheel_link.STL" />
      </geometry>
      <surface>
        <friction>
          <ode>
            <mu>1.0</mu>
            <mu2>1.0</mu2>
          </ode>
        </friction>
      </surface>
    </collision>
  </link>
  <joint
    name="joint_rw"
    type="continuous">
    <origin
      xyz="0 -0.289 0"
      rpy="0 0 0" />
    <parent
      link="base_link" />
    <child
      link="right_wheel_link" />
    <axis
      xyz="0 1 0" />
    <dynamics
      friction = "1.0" />
    <safety_controller
      k_velocity="0" />
  </joint>

  <!-- Imu -->
  <link name="imu_link"/>
  <joint
    name="joint_imu"
    type="fixed">
    <origin
      xyz="0 0 0"
      rpy="0 0 0" />
    <parent
      link="base_link" />
    <child
      link="imu_link" />
    <axis
      xyz="0 0 0" />
    <safety_controller
      k_velocity="0" />
  </joint>

  <!-- Lidar -->
  <link name="laser_link"/>
  <joint
    name="joint_ladar"
    type="fixed">
    <origin
      xyz="0.51 0 0.18"
      rpy="0 0 0" />
    <parent
      link="base_link" />
    <child
      link="laser_link" />
    <axis
      xyz="0 0 0" />
    <safety_controller
      k_velocity="0" />
  </joint>


  <link name="top_laser_link"/>
  <joint
    name="top_joint_ladar"
    type="fixed">
    <origin
      xyz="0.0 0 2.0"
      rpy="0 0 0" />
    <parent
      link="base_link" />
    <child
      link="top_laser_link" />
    <axis
      xyz="0 0 0" />
    <safety_controller
      k_velocity="0" />
  </joint>
  <!--Ultrasonic (TBD) -->

  <!-- <link name="bumper_link">
    <inertial>
        <origin xyz="0.0 0.0 0.0" rpy="0 0.0 0"/>
        <mass value="0.0000000001"/>
        <inertia ixx="0.00000001" ixy="0.00000001" ixz="0.00000001" iyy="0.00000001" iyz="0.00000001" izz="0.00000001"/>
    </inertial>
    <visual>
        <origin xyz="0.3 0.0 1.0" rpy="0.0 0.0 0"/>
        <geometry>
            <cylinder radius="0.5" length="1"/>
        </geometry>
        <material name="red">
            <color rgba="1.0 0.0 0.0 1.0"/>
        </material>
    </visual>
    <collision name="base_collision">
        <origin xyz="0.3 0.0 1.0" rpy="0.0 0.0 0.0"/>
        <geometry>
            <cylinder radius="0.5" length="1"/>
        </geometry>
    </collision>
  </link>
  <joint name="bumper_joint" type="fixed">
      <origin xyz="0.0 0.0 0.0" rpy="0.0 0.0 0.0"/>
      <parent link="base_link"/>
      <child link="bumper_link"/>
  </joint> -->

</robot>
